<?xml version="1.0" encoding="UTF-8"?>
<testsuite name="测试数据源接口"
           tests="5"
           failures="2"
           errors="0"
           skipped="0"
           time="1.212">
  <properties />
            <testcase name="testrename" time="0.132" classname="DataSourceControllerTest">
                <failure type="java.lang.AssertionError"
                  message="expected [{&quot;resultData&quot;:&quot;&quot;,&quot;resultState&quot;:&quot;error&quot;,&quot;resultCode&quot;:&quot;301&quot;}] but found [{&quot;resultData&quot;:&quot;&quot;,&quot;resultState&quot;:&quot;success&quot;,&quot;resultCode&quot;:&quot;200&quot;}]"
              >
<![CDATA[java.lang.AssertionError: expected [{"resultData":"","resultState":"error","resultCode":"301"}] but found [{"resultData":"","resultState":"success","resultCode":"200"}]
  org.testng.Assert.fail(Assert.java:96)
  org.testng.Assert.failNotEquals(Assert.java:776)
  org.testng.Assert.assertEqualsImpl(Assert.java:137)
  org.testng.Assert.assertEquals(Assert.java:118)
  org.testng.Assert.assertEquals(Assert.java:453)
  org.testng.Assert.assertEquals(Assert.java:463)
  DataSourceControllerTest.testrename(DataSourceControllerTest.java:258)
  sun.reflect.NativeMethodAccessorImpl.invoke0(Native Method)
  sun.reflect.NativeMethodAccessorImpl.invoke(NativeMethodAccessorImpl.java:62)
  sun.reflect.DelegatingMethodAccessorImpl.invoke(DelegatingMethodAccessorImpl.java:43)
  java.lang.reflect.Method.invoke(Method.java:498)
  org.testng.internal.MethodInvocationHelper.invokeMethod(MethodInvocationHelper.java:124)
  org.testng.internal.Invoker.invokeMethod(Invoker.java:583)
  org.testng.internal.Invoker.invokeTestMethod(Invoker.java:719)
  org.testng.internal.Invoker.invokeTestMethods(Invoker.java:989)
  org.testng.internal.TestMethodWorker.invokeTestMethods(TestMethodWorker.java:125)
  org.testng.internal.TestMethodWorker.run(TestMethodWorker.java:109)
  org.testng.TestRunner.privateRun(TestRunner.java:648)
  org.testng.TestRunner.run(TestRunner.java:505)
  org.testng.SuiteRunner.runTest(SuiteRunner.java:455)
  org.testng.SuiteRunner.runSequentially(SuiteRunner.java:450)
  org.testng.SuiteRunner.privateRun(SuiteRunner.java:415)
  org.testng.SuiteRunner.run(SuiteRunner.java:364)
  org.testng.SuiteRunnerWorker.runSuite(SuiteRunnerWorker.java:52)
  org.testng.SuiteRunnerWorker.run(SuiteRunnerWorker.java:84)
  org.testng.TestNG.runSuitesSequentially(TestNG.java:1208)
  org.testng.TestNG.runSuitesLocally(TestNG.java:1137)
  org.testng.TestNG.runSuites(TestNG.java:1049)
  org.testng.TestNG.run(TestNG.java:1017)
  org.testng.IDEARemoteTestNG.run(IDEARemoteTestNG.java:72)
  org.testng.RemoteTestNGStarter.main(RemoteTestNGStarter.java:123)
]]>
      </failure>

          </testcase>
            <testcase name="testrename" time="0.287" classname="DataSourceControllerTest">
                <failure type="java.lang.AssertionError"
                  message="expected [{&quot;resultData&quot;:&quot;&quot;,&quot;resultState&quot;:&quot;error&quot;,&quot;resultCode&quot;:&quot;308&quot;}] but found [{&quot;resultData&quot;:&quot;&quot;,&quot;resultState&quot;:&quot;success&quot;,&quot;resultCode&quot;:&quot;200&quot;}]"
              >
<![CDATA[java.lang.AssertionError: expected [{"resultData":"","resultState":"error","resultCode":"308"}] but found [{"resultData":"","resultState":"success","resultCode":"200"}]
  org.testng.Assert.fail(Assert.java:96)
  org.testng.Assert.failNotEquals(Assert.java:776)
  org.testng.Assert.assertEqualsImpl(Assert.java:137)
  org.testng.Assert.assertEquals(Assert.java:118)
  org.testng.Assert.assertEquals(Assert.java:453)
  org.testng.Assert.assertEquals(Assert.java:463)
  DataSourceControllerTest.testrename(DataSourceControllerTest.java:258)
  sun.reflect.NativeMethodAccessorImpl.invoke0(Native Method)
  sun.reflect.NativeMethodAccessorImpl.invoke(NativeMethodAccessorImpl.java:62)
  sun.reflect.DelegatingMethodAccessorImpl.invoke(DelegatingMethodAccessorImpl.java:43)
  java.lang.reflect.Method.invoke(Method.java:498)
  org.testng.internal.MethodInvocationHelper.invokeMethod(MethodInvocationHelper.java:124)
  org.testng.internal.Invoker.invokeMethod(Invoker.java:583)
  org.testng.internal.Invoker.invokeTestMethod(Invoker.java:719)
  org.testng.internal.Invoker.invokeTestMethods(Invoker.java:989)
  org.testng.internal.TestMethodWorker.invokeTestMethods(TestMethodWorker.java:125)
  org.testng.internal.TestMethodWorker.run(TestMethodWorker.java:109)
  org.testng.TestRunner.privateRun(TestRunner.java:648)
  org.testng.TestRunner.run(TestRunner.java:505)
  org.testng.SuiteRunner.runTest(SuiteRunner.java:455)
  org.testng.SuiteRunner.runSequentially(SuiteRunner.java:450)
  org.testng.SuiteRunner.privateRun(SuiteRunner.java:415)
  org.testng.SuiteRunner.run(SuiteRunner.java:364)
  org.testng.SuiteRunnerWorker.runSuite(SuiteRunnerWorker.java:52)
  org.testng.SuiteRunnerWorker.run(SuiteRunnerWorker.java:84)
  org.testng.TestNG.runSuitesSequentially(TestNG.java:1208)
  org.testng.TestNG.runSuitesLocally(TestNG.java:1137)
  org.testng.TestNG.runSuites(TestNG.java:1049)
  org.testng.TestNG.run(TestNG.java:1017)
  org.testng.IDEARemoteTestNG.run(IDEARemoteTestNG.java:72)
  org.testng.RemoteTestNGStarter.main(RemoteTestNGStarter.java:123)
]]>
      </failure>

          </testcase>
  
  
            <testcase name="testrename" time="0.194" classname="DataSourceControllerTest" />
                <testcase name="testrename" time="0.447" classname="DataSourceControllerTest" />
                <testcase name="testrename" time="0.152" classname="DataSourceControllerTest" />
      
</testsuite>
